<?xml version="1.0"?>
<robot xmlns:xacro="http://ros.org/wiki/xacro">

    <!-- Include -->
    <!--xacro:include filename="$(find doogie_description)/urdf/common_properties.xacro"/-->

    <!-- macro: wheel -->
    <xacro:macro name="wheels" params="namespace wheel_name *mesh *origin *axis">

    <link name="${namespace}/wheel/${wheel_name}">

        <inertial>
            <origin 
                xyz="0.0033664 1.419E-05 -1.7243E-07" 
                rpy="0.0 0.0 0.0"/>
            <mass 
                value="0.29447"/>
            <inertia
                ixx="0.2"
                ixy="0"
                ixz="0"
                iyy="0.2"
                iyz="0"
                izz="0.2" />
        </inertial>

        <visual>
            <origin 
                xyz="0.0 0.0 0.0" 
                rpy="0.0 0.0 0.0"/>
            <geometry>
                <xacro:insert_block name="mesh"/>
            </geometry>
        </visual>

        <collision>
            <origin 
                xyz="-0.0025 0.0 0.0" 
                rpy="0.0 1.5708 0.0"/>
            <geometry>
                <cylinder radius="0.015" length="0.005"/>
             </geometry>
        </collision>

    </link>

    <joint name="wheel/${wheel_name}_joint" type="continuous">
        <parent 
            link="${namespace}/base_link"/>
        <child 
            link="${namespace}/wheel/${wheel_name}"/>
        <dynamics 
            friction="0.6"
            damping="10.0"/>
        <xacro:insert_block name="origin"/>
        <xacro:insert_block name="axis"/>
    </joint>

    <transmission name="wheel/${wheel_name}_trans" type="SimpleTransmission">
        <type>transmission_interface/SimpleTransmission</type>
        <actuator name="wheel/${wheel_name}_motor">
            <mechanicalReduction>2</mechanicalReduction>
            <!-- 
                The hardwareInterface tag in below is optional when inside <actuator>, but it is used here to maintain compatibility 
                with ROS releases prior to Indigo. 
            -->
            <hardwareInterface>VelocityJointInterface</hardwareInterface>
        </actuator>
        <joint name="wheel/${wheel_name}_joint">
            <hardwareInterface>hardware_interface/VelocityJointInterface</hardwareInterface>
        </joint>
    </transmission>

    <gazebo reference="${namespace}/wheel/${wheel_name}">
        <kp>1000000.0</kp>
        <kd>1000.0</kd>
        <mu1>5.0</mu1>
        <mu2>5.0</mu2>
        <maxVel>0.5</maxVel>
        <!-- <minDepth>0.0005</minDepth> -->
        <selfCollide>false</selfCollide>
    </gazebo>

    <gazebo reference="wheel/${wheel_name}_joint">
        <provideFeedback>true</provideFeedback>
        <!-- <implicitSpringDamper>true</implicitSpringDamper> -->
    </gazebo>

    <gazebo>
      <plugin name="ft_sensor" filename="libgazebo_ros_ft_sensor.so">
        <updateRate>1</updateRate>
        <topicName>wheel/${wheel_name}_joint/ft_sensor_topic</topicName>
        <jointName>wheel/${wheel_name}_joint</jointName>
      </plugin>
    </gazebo>

    </xacro:macro>

</robot>